Task exception was never retrieved
future: <Task finished name='Task-2' coro=<LaunchService._process_one_event() done, defined at /opt/ros/foxy/lib/python3.8/site-packages/launch/launch_service.py:226> exception=InvalidLaunchFileError('py')>
Traceback (most recent call last):
  File "/opt/ros/foxy/lib/python3.8/site-packages/launch/launch_description_sources/any_launch_file_utilities.py", line 53, in get_launch_description_from_any_launch_file
    return loader(launch_file_path)
  File "/opt/ros/foxy/lib/python3.8/site-packages/launch/launch_description_sources/python_launch_file_utilities.py", line 68, in get_launch_description_from_python_launch_file
    return getattr(launch_file_module, 'generate_launch_description')()
  File "/home/ubuntu20-4-ros2/webots_ros2/install/walking_pattern_generator/share/walking_pattern_generator/launch/robot_launch.py", line 11, in generate_launch_description
    robot_description = pathlib.Path(os.path.join(package_dir, "resource", "webots_robotis_op2_description.urdf")).read_text()
  File "/usr/lib/python3.8/pathlib.py", line 1236, in read_text
    with self.open(mode='r', encoding=encoding, errors=errors) as f:
  File "/usr/lib/python3.8/pathlib.py", line 1222, in open
    return io.open(self, mode, buffering, encoding, errors, newline,
  File "/usr/lib/python3.8/pathlib.py", line 1078, in _opener
    return self._accessor.open(self, flags, mode)
FileNotFoundError: [Errno 2] No such file or directory: '/home/ubuntu20-4-ros2/webots_ros2/install/walking_pattern_generator/share/walking_pattern_generator/resource/webots_robotis_op2_description.urdf'

The above exception was the direct cause of the following exception:

Traceback (most recent call last):
  File "/opt/ros/foxy/lib/python3.8/site-packages/launch/launch_service.py", line 228, in _process_one_event
    await self.__process_event(next_event)
  File "/opt/ros/foxy/lib/python3.8/site-packages/launch/launch_service.py", line 248, in __process_event
    visit_all_entities_and_collect_futures(entity, self.__context))
  File "/opt/ros/foxy/lib/python3.8/site-packages/launch/utilities/visit_all_entities_and_collect_futures_impl.py", line 45, in visit_all_entities_and_collect_futures
    futures_to_return += visit_all_entities_and_collect_futures(sub_entity, context)
  File "/opt/ros/foxy/lib/python3.8/site-packages/launch/utilities/visit_all_entities_and_collect_futures_impl.py", line 45, in visit_all_entities_and_collect_futures
    futures_to_return += visit_all_entities_and_collect_futures(sub_entity, context)
  File "/opt/ros/foxy/lib/python3.8/site-packages/launch/utilities/visit_all_entities_and_collect_futures_impl.py", line 38, in visit_all_entities_and_collect_futures
    sub_entities = entity.visit(context)
  File "/opt/ros/foxy/lib/python3.8/site-packages/launch/action.py", line 108, in visit
    return self.execute(context)
  File "/opt/ros/foxy/lib/python3.8/site-packages/launch/actions/include_launch_description.py", line 130, in execute
    launch_description = self.__launch_description_source.get_launch_description(context)
  File "/opt/ros/foxy/lib/python3.8/site-packages/launch/launch_description_source.py", line 84, in get_launch_description
    self._get_launch_description(self.__expanded_location)
  File "/opt/ros/foxy/lib/python3.8/site-packages/launch/launch_description_sources/any_launch_description_source.py", line 53, in _get_launch_description
    return get_launch_description_from_any_launch_file(location)
  File "/opt/ros/foxy/lib/python3.8/site-packages/launch/launch_description_sources/any_launch_file_utilities.py", line 56, in get_launch_description_from_any_launch_file
    raise InvalidLaunchFileError(extension, likely_errors=exceptions)
launch.invalid_launch_file_error.InvalidLaunchFileError: Caught exception when trying to load file of format [py]: [Errno 2] No such file or directory: '/home/ubuntu20-4-ros2/webots_ros2/install/walking_pattern_generator/share/walking_pattern_generator/resource/webots_robotis_op2_description.urdf'
